{
    "tests": [
        {
            "score": 0.0,
            "max_score": 8.33,
            "name": "test_calculator.py::test_add[load-tests]",
            "output": "\ngroup_name = 'load-tests'\n\n    def new_func(group_name):\n        group_stat = group_stats[group_name]\n        if not group_stat['passed']:\n>           assert group_stat['observed'] == group_stat['expected']\nE           assert 'Traceback (most recent call last):\\n  File \"C:\\\\Users\\\\ahiat\\\\AppData\\\\Local\\\\Programs\\\\Python\\\\Python311\\\\Lib\\\\site-packages\\\\byu_pytest_utils\\\\dialog.py\", line 59, in dialog_exec\\n    executable = executable()\\n                 ^^^^^^^^^^^^\\n  File \"C:\\\\Users\\\\ahiat\\\\CS235\\\\Unit01-Intro-to-cpp\\\\homework1a-intro-to-cpp\\\\test_calculator.py\", line 7, in calculator_bin\\n    return compile_cpp(\\'calculator.cpp\\', output_exec=\\'calculator\\')\\n           ^^^^^^^^^^^^^^^^^^^^^^^^^^^^^^^^^^^^^^^^^^^^^^^^^^^^^^^\\n  File \"C:\\\\Users\\\\ahiat\\\\AppData\\\\Local\\\\Programs\\\\Python\\\\Python311\\\\Lib\\\\site-packages\\\\byu_pytest_utils\\\\cpp_utils.py\", line 12, in compile_cpp\\n    raise Exception(f\\'\"{command}\" failed:\\\\n{proc.stdout}\\')\\nException: \"g++ -Wall -std=c++17 -o calculator calculator.cpp\" failed:\\n\\'g++\\' is not recognized as an internal or external command,\\noperable program or batch file.\\n\\n' == ''\nE             + Traceback (most recent call last):\nE             +   File \"C:\\Users\\ahiat\\AppData\\Local\\Programs\\Python\\Python311\\Lib\\site-packages\\byu_pytest_utils\\dialog.py\", line 59, in dialog_exec\nE             +     executable = executable()\nE             +                  ^^^^^^^^^^^^\nE             +   File \"C:\\Users\\ahiat\\CS235\\Unit01-Intro-to-cpp\\homework1a-intro-to-cpp\\test_calculator.py\", line 7, in calculator_bin\nE             +     return compile_cpp('calculator.cpp', output_exec='calculator')\nE             +            ^^^^^^^^^^^^^^^^^^^^^^^^^^^^^^^^^^^^^^^^^^^^^^^^^^^^^^^\nE             +   File \"C:\\Users\\ahiat\\AppData\\Local\\Programs\\Python\\Python311\\Lib\\site-packages\\byu_pytest_utils\\cpp_utils.py\", line 12, in compile_cpp\nE             +     raise Exception(f'\"{command}\" failed:\\n{proc.stdout}')\nE             + Exception: \"g++ -Wall -std=c++17 -o calculator calculator.cpp\" failed:\nE             + 'g++' is not recognized as an internal or external command,\nE             + operable program or batch file.\nE             +\n\n..\\..\\..\\AppData\\Local\\Programs\\Python\\Python311\\Lib\\site-packages\\byu_pytest_utils\\dialog.py:31: AssertionError",
            "visibility": "visible"
        },
        {
            "score": 0.0,
            "max_score": 8.33,
            "name": "test_calculator.py::test_subtract[load-tests]",
            "output": "\ngroup_name = 'load-tests'\n\n    def new_func(group_name):\n        group_stat = group_stats[group_name]\n        if not group_stat['passed']:\n>           assert group_stat['observed'] == group_stat['expected']\nE           assert 'Traceback (most recent call last):\\n  File \"C:\\\\Users\\\\ahiat\\\\AppData\\\\Local\\\\Programs\\\\Python\\\\Python311\\\\Lib\\\\site-packages\\\\byu_pytest_utils\\\\dialog.py\", line 59, in dialog_exec\\n    executable = executable()\\n                 ^^^^^^^^^^^^\\n  File \"C:\\\\Users\\\\ahiat\\\\CS235\\\\Unit01-Intro-to-cpp\\\\homework1a-intro-to-cpp\\\\test_calculator.py\", line 7, in calculator_bin\\n    return compile_cpp(\\'calculator.cpp\\', output_exec=\\'calculator\\')\\n           ^^^^^^^^^^^^^^^^^^^^^^^^^^^^^^^^^^^^^^^^^^^^^^^^^^^^^^^\\n  File \"C:\\\\Users\\\\ahiat\\\\AppData\\\\Local\\\\Programs\\\\Python\\\\Python311\\\\Lib\\\\site-packages\\\\byu_pytest_utils\\\\cpp_utils.py\", line 12, in compile_cpp\\n    raise Exception(f\\'\"{command}\" failed:\\\\n{proc.stdout}\\')\\nException: \"g++ -Wall -std=c++17 -o calculator calculator.cpp\" failed:\\n\\'g++\\' is not recognized as an internal or external command,\\noperable program or batch file.\\n\\n' == ''\nE             + Traceback (most recent call last):\nE             +   File \"C:\\Users\\ahiat\\AppData\\Local\\Programs\\Python\\Python311\\Lib\\site-packages\\byu_pytest_utils\\dialog.py\", line 59, in dialog_exec\nE             +     executable = executable()\nE             +                  ^^^^^^^^^^^^\nE             +   File \"C:\\Users\\ahiat\\CS235\\Unit01-Intro-to-cpp\\homework1a-intro-to-cpp\\test_calculator.py\", line 7, in calculator_bin\nE             +     return compile_cpp('calculator.cpp', output_exec='calculator')\nE             +            ^^^^^^^^^^^^^^^^^^^^^^^^^^^^^^^^^^^^^^^^^^^^^^^^^^^^^^^\nE             +   File \"C:\\Users\\ahiat\\AppData\\Local\\Programs\\Python\\Python311\\Lib\\site-packages\\byu_pytest_utils\\cpp_utils.py\", line 12, in compile_cpp\nE             +     raise Exception(f'\"{command}\" failed:\\n{proc.stdout}')\nE             + Exception: \"g++ -Wall -std=c++17 -o calculator calculator.cpp\" failed:\nE             + 'g++' is not recognized as an internal or external command,\nE             + operable program or batch file.\nE             +\n\n..\\..\\..\\AppData\\Local\\Programs\\Python\\Python311\\Lib\\site-packages\\byu_pytest_utils\\dialog.py:31: AssertionError",
            "visibility": "visible"
        },
        {
            "score": 0.0,
            "max_score": 8.33,
            "name": "test_calculator.py::test_multiply[load-tests]",
            "output": "\ngroup_name = 'load-tests'\n\n    def new_func(group_name):\n        group_stat = group_stats[group_name]\n        if not group_stat['passed']:\n>           assert group_stat['observed'] == group_stat['expected']\nE           assert 'Traceback (most recent call last):\\n  File \"C:\\\\Users\\\\ahiat\\\\AppData\\\\Local\\\\Programs\\\\Python\\\\Python311\\\\Lib\\\\site-packages\\\\byu_pytest_utils\\\\dialog.py\", line 59, in dialog_exec\\n    executable = executable()\\n                 ^^^^^^^^^^^^\\n  File \"C:\\\\Users\\\\ahiat\\\\CS235\\\\Unit01-Intro-to-cpp\\\\homework1a-intro-to-cpp\\\\test_calculator.py\", line 7, in calculator_bin\\n    return compile_cpp(\\'calculator.cpp\\', output_exec=\\'calculator\\')\\n           ^^^^^^^^^^^^^^^^^^^^^^^^^^^^^^^^^^^^^^^^^^^^^^^^^^^^^^^\\n  File \"C:\\\\Users\\\\ahiat\\\\AppData\\\\Local\\\\Programs\\\\Python\\\\Python311\\\\Lib\\\\site-packages\\\\byu_pytest_utils\\\\cpp_utils.py\", line 12, in compile_cpp\\n    raise Exception(f\\'\"{command}\" failed:\\\\n{proc.stdout}\\')\\nException: \"g++ -Wall -std=c++17 -o calculator calculator.cpp\" failed:\\n\\'g++\\' is not recognized as an internal or external command,\\noperable program or batch file.\\n\\n' == ''\nE             + Traceback (most recent call last):\nE             +   File \"C:\\Users\\ahiat\\AppData\\Local\\Programs\\Python\\Python311\\Lib\\site-packages\\byu_pytest_utils\\dialog.py\", line 59, in dialog_exec\nE             +     executable = executable()\nE             +                  ^^^^^^^^^^^^\nE             +   File \"C:\\Users\\ahiat\\CS235\\Unit01-Intro-to-cpp\\homework1a-intro-to-cpp\\test_calculator.py\", line 7, in calculator_bin\nE             +     return compile_cpp('calculator.cpp', output_exec='calculator')\nE             +            ^^^^^^^^^^^^^^^^^^^^^^^^^^^^^^^^^^^^^^^^^^^^^^^^^^^^^^^\nE             +   File \"C:\\Users\\ahiat\\AppData\\Local\\Programs\\Python\\Python311\\Lib\\site-packages\\byu_pytest_utils\\cpp_utils.py\", line 12, in compile_cpp\nE             +     raise Exception(f'\"{command}\" failed:\\n{proc.stdout}')\nE             + Exception: \"g++ -Wall -std=c++17 -o calculator calculator.cpp\" failed:\nE             + 'g++' is not recognized as an internal or external command,\nE             + operable program or batch file.\nE             +\n\n..\\..\\..\\AppData\\Local\\Programs\\Python\\Python311\\Lib\\site-packages\\byu_pytest_utils\\dialog.py:31: AssertionError",
            "visibility": "visible"
        },
        {
            "score": 0.0,
            "max_score": 8.33,
            "name": "test_calculator.py::test_divide[load-tests]",
            "output": "\ngroup_name = 'load-tests'\n\n    def new_func(group_name):\n        group_stat = group_stats[group_name]\n        if not group_stat['passed']:\n>           assert group_stat['observed'] == group_stat['expected']\nE           assert 'Traceback (most recent call last):\\n  File \"C:\\\\Users\\\\ahiat\\\\AppData\\\\Local\\\\Programs\\\\Python\\\\Python311\\\\Lib\\\\site-packages\\\\byu_pytest_utils\\\\dialog.py\", line 59, in dialog_exec\\n    executable = executable()\\n                 ^^^^^^^^^^^^\\n  File \"C:\\\\Users\\\\ahiat\\\\CS235\\\\Unit01-Intro-to-cpp\\\\homework1a-intro-to-cpp\\\\test_calculator.py\", line 7, in calculator_bin\\n    return compile_cpp(\\'calculator.cpp\\', output_exec=\\'calculator\\')\\n           ^^^^^^^^^^^^^^^^^^^^^^^^^^^^^^^^^^^^^^^^^^^^^^^^^^^^^^^\\n  File \"C:\\\\Users\\\\ahiat\\\\AppData\\\\Local\\\\Programs\\\\Python\\\\Python311\\\\Lib\\\\site-packages\\\\byu_pytest_utils\\\\cpp_utils.py\", line 12, in compile_cpp\\n    raise Exception(f\\'\"{command}\" failed:\\\\n{proc.stdout}\\')\\nException: \"g++ -Wall -std=c++17 -o calculator calculator.cpp\" failed:\\n\\'g++\\' is not recognized as an internal or external command,\\noperable program or batch file.\\n\\n' == ''\nE             + Traceback (most recent call last):\nE             +   File \"C:\\Users\\ahiat\\AppData\\Local\\Programs\\Python\\Python311\\Lib\\site-packages\\byu_pytest_utils\\dialog.py\", line 59, in dialog_exec\nE             +     executable = executable()\nE             +                  ^^^^^^^^^^^^\nE             +   File \"C:\\Users\\ahiat\\CS235\\Unit01-Intro-to-cpp\\homework1a-intro-to-cpp\\test_calculator.py\", line 7, in calculator_bin\nE             +     return compile_cpp('calculator.cpp', output_exec='calculator')\nE             +            ^^^^^^^^^^^^^^^^^^^^^^^^^^^^^^^^^^^^^^^^^^^^^^^^^^^^^^^\nE             +   File \"C:\\Users\\ahiat\\AppData\\Local\\Programs\\Python\\Python311\\Lib\\site-packages\\byu_pytest_utils\\cpp_utils.py\", line 12, in compile_cpp\nE             +     raise Exception(f'\"{command}\" failed:\\n{proc.stdout}')\nE             + Exception: \"g++ -Wall -std=c++17 -o calculator calculator.cpp\" failed:\nE             + 'g++' is not recognized as an internal or external command,\nE             + operable program or batch file.\nE             +\n\n..\\..\\..\\AppData\\Local\\Programs\\Python\\Python311\\Lib\\site-packages\\byu_pytest_utils\\dialog.py:31: AssertionError",
            "visibility": "visible"
        },
        {
            "score": 0.0,
            "max_score": 8.33,
            "name": "test_calculator.py::test_mod[load-tests]",
            "output": "\ngroup_name = 'load-tests'\n\n    def new_func(group_name):\n        group_stat = group_stats[group_name]\n        if not group_stat['passed']:\n>           assert group_stat['observed'] == group_stat['expected']\nE           assert 'Traceback (most recent call last):\\n  File \"C:\\\\Users\\\\ahiat\\\\AppData\\\\Local\\\\Programs\\\\Python\\\\Python311\\\\Lib\\\\site-packages\\\\byu_pytest_utils\\\\dialog.py\", line 59, in dialog_exec\\n    executable = executable()\\n                 ^^^^^^^^^^^^\\n  File \"C:\\\\Users\\\\ahiat\\\\CS235\\\\Unit01-Intro-to-cpp\\\\homework1a-intro-to-cpp\\\\test_calculator.py\", line 7, in calculator_bin\\n    return compile_cpp(\\'calculator.cpp\\', output_exec=\\'calculator\\')\\n           ^^^^^^^^^^^^^^^^^^^^^^^^^^^^^^^^^^^^^^^^^^^^^^^^^^^^^^^\\n  File \"C:\\\\Users\\\\ahiat\\\\AppData\\\\Local\\\\Programs\\\\Python\\\\Python311\\\\Lib\\\\site-packages\\\\byu_pytest_utils\\\\cpp_utils.py\", line 12, in compile_cpp\\n    raise Exception(f\\'\"{command}\" failed:\\\\n{proc.stdout}\\')\\nException: \"g++ -Wall -std=c++17 -o calculator calculator.cpp\" failed:\\n\\'g++\\' is not recognized as an internal or external command,\\noperable program or batch file.\\n\\n' == ''\nE             + Traceback (most recent call last):\nE             +   File \"C:\\Users\\ahiat\\AppData\\Local\\Programs\\Python\\Python311\\Lib\\site-packages\\byu_pytest_utils\\dialog.py\", line 59, in dialog_exec\nE             +     executable = executable()\nE             +                  ^^^^^^^^^^^^\nE             +   File \"C:\\Users\\ahiat\\CS235\\Unit01-Intro-to-cpp\\homework1a-intro-to-cpp\\test_calculator.py\", line 7, in calculator_bin\nE             +     return compile_cpp('calculator.cpp', output_exec='calculator')\nE             +            ^^^^^^^^^^^^^^^^^^^^^^^^^^^^^^^^^^^^^^^^^^^^^^^^^^^^^^^\nE             +   File \"C:\\Users\\ahiat\\AppData\\Local\\Programs\\Python\\Python311\\Lib\\site-packages\\byu_pytest_utils\\cpp_utils.py\", line 12, in compile_cpp\nE             +     raise Exception(f'\"{command}\" failed:\\n{proc.stdout}')\nE             + Exception: \"g++ -Wall -std=c++17 -o calculator calculator.cpp\" failed:\nE             + 'g++' is not recognized as an internal or external command,\nE             + operable program or batch file.\nE             +\n\n..\\..\\..\\AppData\\Local\\Programs\\Python\\Python311\\Lib\\site-packages\\byu_pytest_utils\\dialog.py:31: AssertionError",
            "visibility": "visible"
        },
        {
            "score": 0.0,
            "max_score": 8.35,
            "name": "test_calculator.py::test_invalid_operation[load-tests]",
            "output": "\ngroup_name = 'load-tests'\n\n    def new_func(group_name):\n        group_stat = group_stats[group_name]\n        if not group_stat['passed']:\n>           assert group_stat['observed'] == group_stat['expected']\nE           assert 'Traceback (most recent call last):\\n  File \"C:\\\\Users\\\\ahiat\\\\AppData\\\\Local\\\\Programs\\\\Python\\\\Python311\\\\Lib\\\\site-packages\\\\byu_pytest_utils\\\\dialog.py\", line 59, in dialog_exec\\n    executable = executable()\\n                 ^^^^^^^^^^^^\\n  File \"C:\\\\Users\\\\ahiat\\\\CS235\\\\Unit01-Intro-to-cpp\\\\homework1a-intro-to-cpp\\\\test_calculator.py\", line 7, in calculator_bin\\n    return compile_cpp(\\'calculator.cpp\\', output_exec=\\'calculator\\')\\n           ^^^^^^^^^^^^^^^^^^^^^^^^^^^^^^^^^^^^^^^^^^^^^^^^^^^^^^^\\n  File \"C:\\\\Users\\\\ahiat\\\\AppData\\\\Local\\\\Programs\\\\Python\\\\Python311\\\\Lib\\\\site-packages\\\\byu_pytest_utils\\\\cpp_utils.py\", line 12, in compile_cpp\\n    raise Exception(f\\'\"{command}\" failed:\\\\n{proc.stdout}\\')\\nException: \"g++ -Wall -std=c++17 -o calculator calculator.cpp\" failed:\\n\\'g++\\' is not recognized as an internal or external command,\\noperable program or batch file.\\n\\n' == ''\nE             + Traceback (most recent call last):\nE             +   File \"C:\\Users\\ahiat\\AppData\\Local\\Programs\\Python\\Python311\\Lib\\site-packages\\byu_pytest_utils\\dialog.py\", line 59, in dialog_exec\nE             +     executable = executable()\nE             +                  ^^^^^^^^^^^^\nE             +   File \"C:\\Users\\ahiat\\CS235\\Unit01-Intro-to-cpp\\homework1a-intro-to-cpp\\test_calculator.py\", line 7, in calculator_bin\nE             +     return compile_cpp('calculator.cpp', output_exec='calculator')\nE             +            ^^^^^^^^^^^^^^^^^^^^^^^^^^^^^^^^^^^^^^^^^^^^^^^^^^^^^^^\nE             +   File \"C:\\Users\\ahiat\\AppData\\Local\\Programs\\Python\\Python311\\Lib\\site-packages\\byu_pytest_utils\\cpp_utils.py\", line 12, in compile_cpp\nE             +     raise Exception(f'\"{command}\" failed:\\n{proc.stdout}')\nE             + Exception: \"g++ -Wall -std=c++17 -o calculator calculator.cpp\" failed:\nE             + 'g++' is not recognized as an internal or external command,\nE             + operable program or batch file.\nE             +\n\n..\\..\\..\\AppData\\Local\\Programs\\Python\\Python311\\Lib\\site-packages\\byu_pytest_utils\\dialog.py:31: AssertionError",
            "visibility": "visible"
        },
        {
            "score": 0,
            "max_score": 10,
            "name": "test_numbers_divisible_by.py::test_going_up[load-tests]",
            "output": "\ngroup_name = 'load-tests'\n\n    def new_func(group_name):\n        group_stat = group_stats[group_name]\n        if not group_stat['passed']:\n>           assert group_stat['observed'] == group_stat['expected']\nE           assert 'Traceback (most recent call last):\\n  File \"C:\\\\Users\\\\ahiat\\\\AppData\\\\Local\\\\Programs\\\\Python\\\\Python311\\\\Lib\\\\site-packages\\\\byu_pytest_utils\\\\dialog.py\", line 59, in dialog_exec\\n    executable = executable()\\n                 ^^^^^^^^^^^^\\n  File \"C:\\\\Users\\\\ahiat\\\\CS235\\\\Unit01-Intro-to-cpp\\\\homework1a-intro-to-cpp\\\\test_numbers_divisible_by.py\", line 7, in numbers_divisible_by_bin\\n    return compile_cpp(\\'numbers_divisible_by.cpp\\', output_exec=\\'numbers_divisible_by\\')\\n           ^^^^^^^^^^^^^^^^^^^^^^^^^^^^^^^^^^^^^^^^^^^^^^^^^^^^^^^^^^^^^^^^^^^^^^^^^^^\\n  File \"C:\\\\Users\\\\ahiat\\\\AppData\\\\Local\\\\Programs\\\\Python\\\\Python311\\\\Lib\\\\site-packages\\\\byu_pytest_utils\\\\cpp_utils.py\", line 12, in compile_cpp\\n    raise Exception(f\\'\"{command}\" failed:\\\\n{proc.stdout}\\')\\nException: \"g++ -Wall -std=c++17 -o numbers_divisible_by numbers_divisible_by.cpp\" failed:\\n\\'g++\\' is not recognized as an internal or external command,\\noperable program or batch file.\\n\\n' == ''\nE             + Traceback (most recent call last):\nE             +   File \"C:\\Users\\ahiat\\AppData\\Local\\Programs\\Python\\Python311\\Lib\\site-packages\\byu_pytest_utils\\dialog.py\", line 59, in dialog_exec\nE             +     executable = executable()\nE             +                  ^^^^^^^^^^^^\nE             +   File \"C:\\Users\\ahiat\\CS235\\Unit01-Intro-to-cpp\\homework1a-intro-to-cpp\\test_numbers_divisible_by.py\", line 7, in numbers_divisible_by_bin\nE             +     return compile_cpp('numbers_divisible_by.cpp', output_exec='numbers_divisible_by')\nE             +            ^^^^^^^^^^^^^^^^^^^^^^^^^^^^^^^^^^^^^^^^^^^^^^^^^^^^^^^^^^^^^^^^^^^^^^^^^^^\nE             +   File \"C:\\Users\\ahiat\\AppData\\Local\\Programs\\Python\\Python311\\Lib\\site-packages\\byu_pytest_utils\\cpp_utils.py\", line 12, in compile_cpp\nE             +     raise Exception(f'\"{command}\" failed:\\n{proc.stdout}')\nE             + Exception: \"g++ -Wall -std=c++17 -o numbers_divisible_by numbers_divisible_by.cpp\" failed:\nE             + 'g++' is not recognized as an internal or external command,\nE             + operable program or batch file.\nE             +\n\n..\\..\\..\\AppData\\Local\\Programs\\Python\\Python311\\Lib\\site-packages\\byu_pytest_utils\\dialog.py:31: AssertionError",
            "visibility": "visible"
        },
        {
            "score": 0,
            "max_score": 10,
            "name": "test_numbers_divisible_by.py::test_going_down[load-tests]",
            "output": "\ngroup_name = 'load-tests'\n\n    def new_func(group_name):\n        group_stat = group_stats[group_name]\n        if not group_stat['passed']:\n>           assert group_stat['observed'] == group_stat['expected']\nE           assert 'Traceback (most recent call last):\\n  File \"C:\\\\Users\\\\ahiat\\\\AppData\\\\Local\\\\Programs\\\\Python\\\\Python311\\\\Lib\\\\site-packages\\\\byu_pytest_utils\\\\dialog.py\", line 59, in dialog_exec\\n    executable = executable()\\n                 ^^^^^^^^^^^^\\n  File \"C:\\\\Users\\\\ahiat\\\\CS235\\\\Unit01-Intro-to-cpp\\\\homework1a-intro-to-cpp\\\\test_numbers_divisible_by.py\", line 7, in numbers_divisible_by_bin\\n    return compile_cpp(\\'numbers_divisible_by.cpp\\', output_exec=\\'numbers_divisible_by\\')\\n           ^^^^^^^^^^^^^^^^^^^^^^^^^^^^^^^^^^^^^^^^^^^^^^^^^^^^^^^^^^^^^^^^^^^^^^^^^^^\\n  File \"C:\\\\Users\\\\ahiat\\\\AppData\\\\Local\\\\Programs\\\\Python\\\\Python311\\\\Lib\\\\site-packages\\\\byu_pytest_utils\\\\cpp_utils.py\", line 12, in compile_cpp\\n    raise Exception(f\\'\"{command}\" failed:\\\\n{proc.stdout}\\')\\nException: \"g++ -Wall -std=c++17 -o numbers_divisible_by numbers_divisible_by.cpp\" failed:\\n\\'g++\\' is not recognized as an internal or external command,\\noperable program or batch file.\\n\\n' == ''\nE             + Traceback (most recent call last):\nE             +   File \"C:\\Users\\ahiat\\AppData\\Local\\Programs\\Python\\Python311\\Lib\\site-packages\\byu_pytest_utils\\dialog.py\", line 59, in dialog_exec\nE             +     executable = executable()\nE             +                  ^^^^^^^^^^^^\nE             +   File \"C:\\Users\\ahiat\\CS235\\Unit01-Intro-to-cpp\\homework1a-intro-to-cpp\\test_numbers_divisible_by.py\", line 7, in numbers_divisible_by_bin\nE             +     return compile_cpp('numbers_divisible_by.cpp', output_exec='numbers_divisible_by')\nE             +            ^^^^^^^^^^^^^^^^^^^^^^^^^^^^^^^^^^^^^^^^^^^^^^^^^^^^^^^^^^^^^^^^^^^^^^^^^^^\nE             +   File \"C:\\Users\\ahiat\\AppData\\Local\\Programs\\Python\\Python311\\Lib\\site-packages\\byu_pytest_utils\\cpp_utils.py\", line 12, in compile_cpp\nE             +     raise Exception(f'\"{command}\" failed:\\n{proc.stdout}')\nE             + Exception: \"g++ -Wall -std=c++17 -o numbers_divisible_by numbers_divisible_by.cpp\" failed:\nE             + 'g++' is not recognized as an internal or external command,\nE             + operable program or batch file.\nE             +\n\n..\\..\\..\\AppData\\Local\\Programs\\Python\\Python311\\Lib\\site-packages\\byu_pytest_utils\\dialog.py:31: AssertionError",
            "visibility": "visible"
        },
        {
            "score": 0,
            "max_score": 10,
            "name": "test_numbers_divisible_by.py::test_includes_bounds_going_up[load-tests]",
            "output": "\ngroup_name = 'load-tests'\n\n    def new_func(group_name):\n        group_stat = group_stats[group_name]\n        if not group_stat['passed']:\n>           assert group_stat['observed'] == group_stat['expected']\nE           assert 'Traceback (most recent call last):\\n  File \"C:\\\\Users\\\\ahiat\\\\AppData\\\\Local\\\\Programs\\\\Python\\\\Python311\\\\Lib\\\\site-packages\\\\byu_pytest_utils\\\\dialog.py\", line 59, in dialog_exec\\n    executable = executable()\\n                 ^^^^^^^^^^^^\\n  File \"C:\\\\Users\\\\ahiat\\\\CS235\\\\Unit01-Intro-to-cpp\\\\homework1a-intro-to-cpp\\\\test_numbers_divisible_by.py\", line 7, in numbers_divisible_by_bin\\n    return compile_cpp(\\'numbers_divisible_by.cpp\\', output_exec=\\'numbers_divisible_by\\')\\n           ^^^^^^^^^^^^^^^^^^^^^^^^^^^^^^^^^^^^^^^^^^^^^^^^^^^^^^^^^^^^^^^^^^^^^^^^^^^\\n  File \"C:\\\\Users\\\\ahiat\\\\AppData\\\\Local\\\\Programs\\\\Python\\\\Python311\\\\Lib\\\\site-packages\\\\byu_pytest_utils\\\\cpp_utils.py\", line 12, in compile_cpp\\n    raise Exception(f\\'\"{command}\" failed:\\\\n{proc.stdout}\\')\\nException: \"g++ -Wall -std=c++17 -o numbers_divisible_by numbers_divisible_by.cpp\" failed:\\n\\'g++\\' is not recognized as an internal or external command,\\noperable program or batch file.\\n\\n' == ''\nE             + Traceback (most recent call last):\nE             +   File \"C:\\Users\\ahiat\\AppData\\Local\\Programs\\Python\\Python311\\Lib\\site-packages\\byu_pytest_utils\\dialog.py\", line 59, in dialog_exec\nE             +     executable = executable()\nE             +                  ^^^^^^^^^^^^\nE             +   File \"C:\\Users\\ahiat\\CS235\\Unit01-Intro-to-cpp\\homework1a-intro-to-cpp\\test_numbers_divisible_by.py\", line 7, in numbers_divisible_by_bin\nE             +     return compile_cpp('numbers_divisible_by.cpp', output_exec='numbers_divisible_by')\nE             +            ^^^^^^^^^^^^^^^^^^^^^^^^^^^^^^^^^^^^^^^^^^^^^^^^^^^^^^^^^^^^^^^^^^^^^^^^^^^\nE             +   File \"C:\\Users\\ahiat\\AppData\\Local\\Programs\\Python\\Python311\\Lib\\site-packages\\byu_pytest_utils\\cpp_utils.py\", line 12, in compile_cpp\nE             +     raise Exception(f'\"{command}\" failed:\\n{proc.stdout}')\nE             + Exception: \"g++ -Wall -std=c++17 -o numbers_divisible_by numbers_divisible_by.cpp\" failed:\nE             + 'g++' is not recognized as an internal or external command,\nE             + operable program or batch file.\nE             +\n\n..\\..\\..\\AppData\\Local\\Programs\\Python\\Python311\\Lib\\site-packages\\byu_pytest_utils\\dialog.py:31: AssertionError",
            "visibility": "visible"
        },
        {
            "score": 0,
            "max_score": 10,
            "name": "test_numbers_divisible_by.py::test_includes_bounds_going_down[load-tests]",
            "output": "\ngroup_name = 'load-tests'\n\n    def new_func(group_name):\n        group_stat = group_stats[group_name]\n        if not group_stat['passed']:\n>           assert group_stat['observed'] == group_stat['expected']\nE           assert 'Traceback (most recent call last):\\n  File \"C:\\\\Users\\\\ahiat\\\\AppData\\\\Local\\\\Programs\\\\Python\\\\Python311\\\\Lib\\\\site-packages\\\\byu_pytest_utils\\\\dialog.py\", line 59, in dialog_exec\\n    executable = executable()\\n                 ^^^^^^^^^^^^\\n  File \"C:\\\\Users\\\\ahiat\\\\CS235\\\\Unit01-Intro-to-cpp\\\\homework1a-intro-to-cpp\\\\test_numbers_divisible_by.py\", line 7, in numbers_divisible_by_bin\\n    return compile_cpp(\\'numbers_divisible_by.cpp\\', output_exec=\\'numbers_divisible_by\\')\\n           ^^^^^^^^^^^^^^^^^^^^^^^^^^^^^^^^^^^^^^^^^^^^^^^^^^^^^^^^^^^^^^^^^^^^^^^^^^^\\n  File \"C:\\\\Users\\\\ahiat\\\\AppData\\\\Local\\\\Programs\\\\Python\\\\Python311\\\\Lib\\\\site-packages\\\\byu_pytest_utils\\\\cpp_utils.py\", line 12, in compile_cpp\\n    raise Exception(f\\'\"{command}\" failed:\\\\n{proc.stdout}\\')\\nException: \"g++ -Wall -std=c++17 -o numbers_divisible_by numbers_divisible_by.cpp\" failed:\\n\\'g++\\' is not recognized as an internal or external command,\\noperable program or batch file.\\n\\n' == ''\nE             + Traceback (most recent call last):\nE             +   File \"C:\\Users\\ahiat\\AppData\\Local\\Programs\\Python\\Python311\\Lib\\site-packages\\byu_pytest_utils\\dialog.py\", line 59, in dialog_exec\nE             +     executable = executable()\nE             +                  ^^^^^^^^^^^^\nE             +   File \"C:\\Users\\ahiat\\CS235\\Unit01-Intro-to-cpp\\homework1a-intro-to-cpp\\test_numbers_divisible_by.py\", line 7, in numbers_divisible_by_bin\nE             +     return compile_cpp('numbers_divisible_by.cpp', output_exec='numbers_divisible_by')\nE             +            ^^^^^^^^^^^^^^^^^^^^^^^^^^^^^^^^^^^^^^^^^^^^^^^^^^^^^^^^^^^^^^^^^^^^^^^^^^^\nE             +   File \"C:\\Users\\ahiat\\AppData\\Local\\Programs\\Python\\Python311\\Lib\\site-packages\\byu_pytest_utils\\cpp_utils.py\", line 12, in compile_cpp\nE             +     raise Exception(f'\"{command}\" failed:\\n{proc.stdout}')\nE             + Exception: \"g++ -Wall -std=c++17 -o numbers_divisible_by numbers_divisible_by.cpp\" failed:\nE             + 'g++' is not recognized as an internal or external command,\nE             + operable program or batch file.\nE             +\n\n..\\..\\..\\AppData\\Local\\Programs\\Python\\Python311\\Lib\\site-packages\\byu_pytest_utils\\dialog.py:31: AssertionError",
            "visibility": "visible"
        },
        {
            "score": 0,
            "max_score": 10,
            "name": "test_numbers_divisible_by.py::test_negative_numbers_and_zero[load-tests]",
            "output": "\ngroup_name = 'load-tests'\n\n    def new_func(group_name):\n        group_stat = group_stats[group_name]\n        if not group_stat['passed']:\n>           assert group_stat['observed'] == group_stat['expected']\nE           assert 'Traceback (most recent call last):\\n  File \"C:\\\\Users\\\\ahiat\\\\AppData\\\\Local\\\\Programs\\\\Python\\\\Python311\\\\Lib\\\\site-packages\\\\byu_pytest_utils\\\\dialog.py\", line 59, in dialog_exec\\n    executable = executable()\\n                 ^^^^^^^^^^^^\\n  File \"C:\\\\Users\\\\ahiat\\\\CS235\\\\Unit01-Intro-to-cpp\\\\homework1a-intro-to-cpp\\\\test_numbers_divisible_by.py\", line 7, in numbers_divisible_by_bin\\n    return compile_cpp(\\'numbers_divisible_by.cpp\\', output_exec=\\'numbers_divisible_by\\')\\n           ^^^^^^^^^^^^^^^^^^^^^^^^^^^^^^^^^^^^^^^^^^^^^^^^^^^^^^^^^^^^^^^^^^^^^^^^^^^\\n  File \"C:\\\\Users\\\\ahiat\\\\AppData\\\\Local\\\\Programs\\\\Python\\\\Python311\\\\Lib\\\\site-packages\\\\byu_pytest_utils\\\\cpp_utils.py\", line 12, in compile_cpp\\n    raise Exception(f\\'\"{command}\" failed:\\\\n{proc.stdout}\\')\\nException: \"g++ -Wall -std=c++17 -o numbers_divisible_by numbers_divisible_by.cpp\" failed:\\n\\'g++\\' is not recognized as an internal or external command,\\noperable program or batch file.\\n\\n' == ''\nE             + Traceback (most recent call last):\nE             +   File \"C:\\Users\\ahiat\\AppData\\Local\\Programs\\Python\\Python311\\Lib\\site-packages\\byu_pytest_utils\\dialog.py\", line 59, in dialog_exec\nE             +     executable = executable()\nE             +                  ^^^^^^^^^^^^\nE             +   File \"C:\\Users\\ahiat\\CS235\\Unit01-Intro-to-cpp\\homework1a-intro-to-cpp\\test_numbers_divisible_by.py\", line 7, in numbers_divisible_by_bin\nE             +     return compile_cpp('numbers_divisible_by.cpp', output_exec='numbers_divisible_by')\nE             +            ^^^^^^^^^^^^^^^^^^^^^^^^^^^^^^^^^^^^^^^^^^^^^^^^^^^^^^^^^^^^^^^^^^^^^^^^^^^\nE             +   File \"C:\\Users\\ahiat\\AppData\\Local\\Programs\\Python\\Python311\\Lib\\site-packages\\byu_pytest_utils\\cpp_utils.py\", line 12, in compile_cpp\nE             +     raise Exception(f'\"{command}\" failed:\\n{proc.stdout}')\nE             + Exception: \"g++ -Wall -std=c++17 -o numbers_divisible_by numbers_divisible_by.cpp\" failed:\nE             + 'g++' is not recognized as an internal or external command,\nE             + operable program or batch file.\nE             +\n\n..\\..\\..\\AppData\\Local\\Programs\\Python\\Python311\\Lib\\site-packages\\byu_pytest_utils\\dialog.py:31: AssertionError",
            "visibility": "visible"
        }
    ]
}